<?xml version="1.0" ?>
<!-- =================================================================================== -->
<!-- |    This document was autogenerated by xacro from kachaka.urdf.xacro             | -->
<!-- |    EDITING THIS FILE BY HAND IS NOT RECOMMENDED                                 | -->
<!-- =================================================================================== -->
<robot name="kachaka">
  <material name="body">
    <color rgba="0.2175 0.2355 0.246 1.0"/>
  </material>
  <material name="tire">
    <color rgba="0.3 0.3 0.3 1.0"/>
  </material>
  <material name="black">
    <color rgba="0.0 0.0 0.0 1.0"/>
  </material>

  <link name="base_footprint"/>
  <!-- base_footprint -->
  <joint name="base_footprint_joint" type="fixed">
    <parent link="base_footprint"/>
    <child link="base_link"/>
  </joint>

  <link name="base_link">
    <inertial>
      <mass value="6.4"/>
      <origin rpy="0 0 0" xyz="0 0 0"/>
      <inertia ixx="2.1342e-02" ixy="0" ixz="0" iyy="2.1342e-02" iyz="0" izz="4.2667e-02"/>
    </inertial>
    <visual>
      <origin rpy="0 0 0" xyz="-0.150 -0.120 0.0"/>
      <geometry>
        <mesh filename="kachaka_description/meshes/kachaka/body2.stl"/>
      </geometry>
      <material name="body"/>
    </visual>
    <collision>
      <origin rpy="0 0 0" xyz="0.0435 0.0 0.1"/>
      <geometry>
        <box size="0.387 0.240 0.095"/>
      </geometry>
      <material name="body"/>
    </collision>
  </link>

  <!-- Wheel(right) -->
  <joint name="base_r_drive_wheel_joint" type="continuous">
    <parent link="base_link"/>
    <child link="base_r_drive_wheel_link"/>
    <origin rpy="0 0 0" xyz="0.0 -0.100 0.045"/>
    <axis xyz="0 1 0"/>
    <limit effort="100" velocity="10"/>
  </joint>

  <link name="base_r_drive_wheel_link">
    <inertial>
      <mass value="0.2"/>
      <origin rpy="0 0 0" xyz="0 0 0"/>
      <inertia ixx="0.001" ixy="0" ixz="0" iyy="0.001" iyz="0" izz="0.001"/>
    </inertial>
    <visual>
      <!-- <origin rpy="0 0 0" xyz="0 0 0"/>
      <geometry>
        <mesh filename="kachaka_description/meshes/kachaka/right_tire.stl" scale="1.0 1.0 1.0"/>
      </geometry> -->
      <origin rpy="1.5707963267948966 0 0" xyz="0 0 0"/>
      <geometry>
        <cylinder length="0.025" radius="0.045"/>
      </geometry>
      <material name="tire"/>
    </visual>
    <collision>
      <origin rpy="1.5707963267948966 0 0" xyz="0 0 0"/>
      <geometry>
        <cylinder length="0.025" radius="0.045"/>
      </geometry>
      <material name="tire"/>
    </collision>
  </link>
  <link name="laser_frame">
    <inertial>
      <mass value="0.2"/>
      <origin rpy="0 0 0" xyz="0 0 0"/>
      <inertia ixx="0.001" ixy="0" ixz="0" iyy="0.001" iyz="0" izz="0.001"/>
    </inertial>
  </link>

  <!-- Wheel(left) -->
  <joint name="base_l_drive_wheel_joint" type="continuous">
    <parent link="base_link"/>
    <child link="base_l_drive_wheel_link"/>
    <origin rpy="0 0 0" xyz="0.0 0.100 0.045"/>
    <axis xyz="0 1 0"/>
    <limit effort="100" velocity="10"/>
  </joint>

  <link name="base_l_drive_wheel_link">
    <inertial>
      <mass value="0.2"/>
      <origin rpy="0 0 0" xyz="0 0 0"/>
      <inertia ixx="0.001" ixy="0" ixz="0" iyy="0.001" iyz="0" izz="0.001"/>
    </inertial>
    <visual>
      <!-- <origin rpy="0 0 0" xyz="0 0 0"/>
      <geometry>
        <mesh filename="kachaka_description/meshes/kachaka/left_tire.stl" scale="1.0 1.0 1.0"/>
      </geometry> -->
      <origin rpy="1.5707963267948966 0 0" xyz="0 0 0"/>
      <geometry>
        <cylinder length="0.025" radius="0.045"/>
      </geometry>
      <material name="tire"/>
    </visual>
    <collision>
      <origin rpy="1.5707963267948966 0 0" xyz="0 0 0"/>
      <geometry>
        <cylinder length="0.025" radius="0.045"/>
      </geometry>
      <material name="tire"/>
    </collision>
  </link>
  <!-- 2D LiDAR -->
  <joint name="lidar_joint" type="fixed">
    <parent link="base_link"/>
    <child link="laser_frame"/>
    <origin rpy="0 0 1.5707963267948966" xyz="0.156 0 0.1049"/>
  </joint>

  <!-- Camera(front) -->
  <joint name="camera_front_joint" type="fixed">
    <parent link="base_link"/>
    <child link="camera_front_link"/>
    <origin rpy="-1.5707963267948966 0 -1.5707963267948966" xyz="0.20959999999999998 0 0.070"/>
  </joint>

  <link name="camera_front_link">
    <inertial>
      <mass value="0.2"/>
      <origin rpy="0 0 0" xyz="0 0 0"/>
      <inertia ixx="0.001" ixy="0" ixz="0" iyy="0.001" iyz="0" izz="0.001"/>
    </inertial>
  </link>

  <!-- Camera(back) -->
   <joint name="camera_back_joint" type="fixed">
    <parent link="base_link"/>
    <child link="camera_back_link"/>
    <origin rpy="-1.5707963267948966 0 1.5707963267948966" xyz="-0.13999999999999999 0 0.070"/>
  </joint>

   <link name="camera_back_link">
    <inertial>
      <mass value="0.2"/>
      <origin rpy="0 0 0" xyz="0 0 0"/>
      <inertia ixx="0.001" ixy="0" ixz="0" iyy="0.001" iyz="0" izz="0.001"/>
    </inertial>
  </link>


  <!-- ToF camera -->

  <joint name="tof_joint" type="fixed">
    <parent link="base_link"/>
    <child link="tof_link"/>
    <origin rpy="-0.7853981633974483 0 -1.5707963267948966" xyz="0.221 0.0 0.0418"/>
  </joint>

  <link name="tof_link">
    <inertial>
      <mass value="0.2"/>
      <origin rpy="0 0 0" xyz="0 0 0"/>
      <inertia ixx="0.001" ixy="0" ixz="0" iyy="0.001" iyz="0" izz="0.001"/>
    </inertial>
  </link>

  <!-- Docking
  <joint name="docking_joint" type="prismatic">
    <parent link="base_link"/>
    <child link="docking_link"/>
    <axis xyz="0 0 1.0"/>
    <origin rpy="0 0 0" xyz="0 0 0"/>
    <limit effort="1.0" lower="0.0" upper="0.012" velocity="1.0"/>
  </joint>
  <link name="docking_link">
    <inertial>
      <mass value="0.2"/>
      <origin rpy="0 0 0" xyz="0 0 0.1075"/>
      <inertia ixx="3.5000000000000004e-05" ixy="0" ixz="0" iyy="3.5000000000000004e-05" iyz="0" izz="6.250000000000001e-05"/>
      <origin rpy="0 0 0" xyz="0 0 0"/>
      <inertia ixx="0.001" ixy="0" ixz="0" iyy="0.001" iyz="0" izz="0.001"/>
    </inertial>
    <visual>
      <origin rpy="0 0 0" xyz="0 0 0.073"/>
      <geometry>
        <mesh filename="achaka_description/meshes/kachaka/solenoid.stl" scale="1.0 1.0 1.0"/>
      </geometry>
      <material name="body"/>
    </visual>
    <collision>
      <origin rpy="0 0 0" xyz="0 0 0.1075"/>
      <geometry>
        <cylinder length="0.015" radius="0.025"/>
      </geometry>
      <material name="body"/>
    </collision>
  </link> -->

  <!-- IMU -->
  <link name="imu_link"/>
  <joint name="imu_joint" type="fixed">
    <parent link="base_link"/>
    <child link="imu_link"/>
    <origin rpy="0 0 0" xyz="0.0756 -0.0655 0.05146"/>
  </joint>
  
  <!-- sub_left_wheel -->
    <!-- X軸回転ジョイント（キャスターをベースリンクに接続） -->
    <!-- base_link から x軸回転用の中間リンクへ -->
    <joint name="caster_left_joint_x" type="continuous">
    <parent link="base_link"/>
    <child link="caster_x_link"/>
    <origin xyz="0.19 0.075 0.02" rpy="0 0 0"/>  <!-- 球体中心に一致（高さ0.02） -->
    <axis xyz="1 0 0"/>
    </joint>

    <link name="caster_x_link"/>

    <!-- Y軸回転 -->
    <joint name="caster_left_joint_y" type="continuous">
    <parent link="caster_x_link"/>
    <child link="caster_sphere_left"/>
    <origin xyz="0 0 0" rpy="0 0 0"/>
    <axis xyz="0 1 0"/>
    </joint>

    <!-- 球体リンク -->
    <link name="caster_sphere_left">
    <inertial>
        <origin xyz="0 0 0" rpy="0 0 0"/>
        <mass value="0.1"/>
        <inertia ixx="5e-4" iyy="5e-4" izz="5e-4" ixy="0" ixz="0" iyz="0"/>
    </inertial>
    <contact>
      <lateral_friction>0.1</lateral_friction>
      <spinning_friction>0.1</spinning_friction>
    </contact>
    <visual>
        <origin xyz="0 0 0" rpy="0 0 0"/>
        <geometry>
        <sphere radius="0.02"/>
        </geometry>
        <material name="gray"/>
    </visual>
    <collision>
        <origin xyz="0 0 0" rpy="0 0 0"/>
        <geometry>
        <sphere radius="0.02"/>
        </geometry>
        <surface>
        <friction>
            <ode>
            <mu>0.8</mu>
            <mu2>0.8</mu2>
            </ode>
        </friction>
        </surface>
    </collision>
    </link>

    <!-- sub_left_wheel -->
    <!-- X軸回転ジョイント（キャスターをベースリンクに接続） -->
    <!-- base_link から x軸回転用の中間リンクへ -->
    <joint name="caster_right_joint_x" type="continuous">
    <parent link="base_link"/>
    <child link="caster_y_link"/>
    <origin xyz="0.19 -0.075 0.02" rpy="0 0 0"/>  <!-- 球体中心に一致（高さ0.02） -->
    <axis xyz="1 0 0"/>
    </joint>

    <link name="caster_y_link"/>
    <!-- Y軸回転 -->
    <joint name="caster_right_joint_y" type="continuous">
    <parent link="caster_y_link"/>
    <child link="caster_sphere_right"/>
    <origin xyz="0 0 0" rpy="0 0 0"/>
    <axis xyz="0 1 0"/>
    </joint>

    <!-- 球体リンク -->
    <link name="caster_sphere_right">
    <inertial>
        <origin xyz="0 0 0" rpy="0 0 0"/>
        <mass value="1"/>
        <inertia ixx="5e-4" iyy="5e-4" izz="5e-4" ixy="0" ixz="0" iyz="0"/>
    </inertial>
    <contact>
      <lateral_friction>0.1</lateral_friction>
      <spinning_friction>0.1</spinning_friction>
    </contact>
    <visual>
        <origin xyz="0 0 0" rpy="0 0 0"/>
        <geometry>
        <sphere radius="0.02"/>
        </geometry>
        <material name="gray"/>
    </visual>
    <collision>
        <origin xyz="0 0 0" rpy="0 0 0"/>
        <geometry>
        <sphere radius="0.02"/>
        </geometry>
            <surface>
            <friction>
                <ode>
                <mu>0.8</mu>
                <mu2>0.8</mu2>
                </ode>
            </friction>
            </surface>
        </collision>
    </link>

</robot>
